
    <mujoco>
    <compiler angle="radian" meshdir="assets/" discardvisual="false" />
    <option timestep="0.004" density="1.2" viscosity="2e-05" integrator="Euler" gravity="0 0 -9.81" wind="0 0 0" />

    <visual>
        <global azimuth="-20" elevation="-20" ellipsoidinertia="true" />
        <headlight ambient="0.3 0.3 0.3" diffuse="0.6 0.6 0.6" specular="0 0 0" />
        <rgba haze="0.15 0.25 0.35 1" />
    </visual>

    <default>
        <default class="cf2">
            <site group="5" />
            <default class="visual">
                <geom type="mesh" contype="0" conaffinity="0" group="2" />
            </default>
            <default class="collision">
                <geom type="mesh" group="3" />
            </default>
        </default>
    </default>

    <extension>
        <plugin plugin="mujoco.elasticity.cable">
            <instance name="compositecable0_" /> 
<instance name="compositecable1_" /> 

        </plugin>
    </extension>

    <asset>
        <texture type="skybox" builtin="gradient" rgb1="0.3 0.5 0.7" rgb2="0 0 0" width="512"
            height="3072" />
        <texture type="2d" name="groundplane" builtin="checker" mark="edge" rgb1="0.2 0.3 0.4"
            rgb2="0.1 0.2 0.3" markrgb="0.8 0.8 0.8" width="300" height="300" />
        <material name="polished_plastic" rgba="0.631 0.659 0.678 1" />
        <material name="polished_gold" rgba="0.969 0.878 0.6 1" />
        <material name="medium_gloss_plastic" rgba="0.109 0.184 0 1" />
        <material name="propeller_plastic" rgba="0.792 0.82 0.933 1" />
        <material name="white" />
        <material name="body_frame_plastic" rgba="0.102 0.102 0.102 1" />
        <material name="burnished_chrome" rgba="0.898 0.898 0.898 1" />
        <material name="groundplane" texture="groundplane" texuniform="true" texrepeat="10 10"
            reflectance="0" />
        <mesh name="cf2_0" file="cf2_0.obj" />
        <mesh name="cf2_1" file="cf2_1.obj" />
        <mesh name="cf2_2" file="cf2_2.obj" />
        <mesh name="cf2_3" file="cf2_3.obj" />
        <mesh name="cf2_4" file="cf2_4.obj" />
        <mesh name="cf2_5" file="cf2_5.obj" />
        <mesh name="cf2_6" file="cf2_6.obj" />
        <mesh name="cf2_collision_0" file="cf2_collision_0.obj" />
        <mesh name="cf2_collision_1" file="cf2_collision_1.obj" />
        <mesh name="cf2_collision_2" file="cf2_collision_2.obj" />
        <mesh name="cf2_collision_3" file="cf2_collision_3.obj" />
        <mesh name="cf2_collision_4" file="cf2_collision_4.obj" />
        <mesh name="cf2_collision_5" file="cf2_collision_5.obj" />
        <mesh name="cf2_collision_6" file="cf2_collision_6.obj" />
        <mesh name="cf2_collision_7" file="cf2_collision_7.obj" />
        <mesh name="cf2_collision_8" file="cf2_collision_8.obj" />
        <mesh name="cf2_collision_9" file="cf2_collision_9.obj" />
        <mesh name="cf2_collision_10" file="cf2_collision_10.obj" />
        <mesh name="cf2_collision_11" file="cf2_collision_11.obj" />
        <mesh name="cf2_collision_12" file="cf2_collision_12.obj" />
        <mesh name="cf2_collision_13" file="cf2_collision_13.obj" />
        <mesh name="cf2_collision_14" file="cf2_collision_14.obj" />
        <mesh name="cf2_collision_15" file="cf2_collision_15.obj" />
        <mesh name="cf2_collision_16" file="cf2_collision_16.obj" />
        <mesh name="cf2_collision_17" file="cf2_collision_17.obj" />
        <mesh name="cf2_collision_18" file="cf2_collision_18.obj" />
        <mesh name="cf2_collision_19" file="cf2_collision_19.obj" />
        <mesh name="cf2_collision_20" file="cf2_collision_20.obj" />
        <mesh name="cf2_collision_21" file="cf2_collision_21.obj" />
        <mesh name="cf2_collision_22" file="cf2_collision_22.obj" />
        <mesh name="cf2_collision_23" file="cf2_collision_23.obj" />
        <mesh name="cf2_collision_24" file="cf2_collision_24.obj" />
        <mesh name="cf2_collision_25" file="cf2_collision_25.obj" />
        <mesh name="cf2_collision_26" file="cf2_collision_26.obj" />
        <mesh name="cf2_collision_27" file="cf2_collision_27.obj" />
        <mesh name="cf2_collision_28" file="cf2_collision_28.obj" />
        <mesh name="cf2_collision_29" file="cf2_collision_29.obj" />
        <mesh name="cf2_collision_30" file="cf2_collision_30.obj" />
        <mesh name="cf2_collision_31" file="cf2_collision_31.obj" />
    </asset>

    <worldbody>
        <geom name="goal_marker" contype="0" conaffinity="0" pos="0 0 1" size="0.02" rgba="1 0 0 0.8" />
        <geom name="floor" size="0 0 0.05" type="plane" material="groundplane" />
        <light pos="0 0 1.5" dir="0 0 -1" directional="true" />

        <site name="q0_start" pos="0 -0.15 1.1" euler="0 0 0" />
<site name="q1_start" pos="0 0.15 1.1" euler="0 0 0" />

        <!-- Payload start site-->
        

        
            <body name="payload" pos="0.0 0.0 1.0" >
            <camera name="track" pos="-1 0 0.5" quat="0.601501 0.371748 -0.371748 -0.601501"
                mode="trackcom" />
            <joint type="free" actuatorfrclimited="false" damping="0.00001"/>
            <geom size="0.007 0.01" type="cylinder" mass="0.001" rgba="0.8 0.8 0.8 1" />
            <site name="payload_s" pos="0 0 0.01" />
            
            

            <!-- Quad 0 -->
            <body name="q0_cable_chain" pos="0 0 0.01" euler="0 0 -1.5707963267948966">
            
        <body name="q0_cable_B_first">
            <joint name="q0_cable_J_first" pos="0 0 0" type="ball" group="3"
                actuatorfrclimited="false" damping="1e-05" />
            <geom name="q0_cable_G0" size="0.0005 0.0075" pos="0.0075 0 0"
            quat="0.707107 0 -0.707107 0" type="capsule" condim="1"
            mass="5e-06" rgba="0.1 0.8 0.1 1" />
            <site name="q0_cable_S_first" pos="0 0 0" group="3" />
            <plugin instance="compositecable0_" />
        
            <body name="q0_cable_B_1" pos="0.015 0 0">
             <joint name="q0_cable_J_1" pos="0 0 0" type="ball" group="3"
                 actuatorfrclimited="false" damping="1e-05" />
             <geom name="q0_cable_G1" size="0.0005 0.0075" pos="0.0075 0 0"
                 quat="0.707107 0 -0.707107 0" type="capsule" condim="1"
                 mass="5e-06" rgba="0.1 0.8 0.1 1" />
             <plugin instance="compositecable0_" />
            
            <body name="q0_cable_B_2" pos="0.015 0 0">
             <joint name="q0_cable_J_2" pos="0 0 0" type="ball" group="3"
                 actuatorfrclimited="false" damping="1e-05" />
             <geom name="q0_cable_G2" size="0.0005 0.0075" pos="0.0075 0 0"
                 quat="0.707107 0 -0.707107 0" type="capsule" condim="1"
                 mass="5e-06" rgba="0.1 0.8 0.1 1" />
             <plugin instance="compositecable0_" />
            
            <body name="q0_cable_B_3" pos="0.015 0 0">
             <joint name="q0_cable_J_3" pos="0 0 0" type="ball" group="3"
                 actuatorfrclimited="false" damping="1e-05" />
             <geom name="q0_cable_G3" size="0.0005 0.0075" pos="0.0075 0 0"
                 quat="0.707107 0 -0.707107 0" type="capsule" condim="1"
                 mass="5e-06" rgba="0.1 0.8 0.1 1" />
             <plugin instance="compositecable0_" />
            
            <body name="q0_cable_B_4" pos="0.015 0 0">
             <joint name="q0_cable_J_4" pos="0 0 0" type="ball" group="3"
                 actuatorfrclimited="false" damping="1e-05" />
             <geom name="q0_cable_G4" size="0.0005 0.0075" pos="0.0075 0 0"
                 quat="0.707107 0 -0.707107 0" type="capsule" condim="1"
                 mass="5e-06" rgba="0.1 0.8 0.1 1" />
             <plugin instance="compositecable0_" />
            
            <body name="q0_cable_B_5" pos="0.015 0 0">
             <joint name="q0_cable_J_5" pos="0 0 0" type="ball" group="3"
                 actuatorfrclimited="false" damping="1e-05" />
             <geom name="q0_cable_G5" size="0.0005 0.0075" pos="0.0075 0 0"
                 quat="0.707107 0 -0.707107 0" type="capsule" condim="1"
                 mass="5e-06" rgba="0.1 0.8 0.1 1" />
             <plugin instance="compositecable0_" />
            
            <body name="q0_cable_B_6" pos="0.015 0 0">
             <joint name="q0_cable_J_6" pos="0 0 0" type="ball" group="3"
                 actuatorfrclimited="false" damping="1e-05" />
             <geom name="q0_cable_G6" size="0.0005 0.0075" pos="0.0075 0 0"
                 quat="0.707107 0 -0.707107 0" type="capsule" condim="1"
                 mass="5e-06" rgba="0.1 0.8 0.1 1" />
             <plugin instance="compositecable0_" />
            
            <body name="q0_cable_B_7" pos="0.015 0 0">
             <joint name="q0_cable_J_7" pos="0 0 0" type="ball" group="3"
                 actuatorfrclimited="false" damping="1e-05" />
             <geom name="q0_cable_G7" size="0.0005 0.0075" pos="0.0075 0 0"
                 quat="0.707107 0 -0.707107 0" type="capsule" condim="1"
                 mass="5e-06" rgba="0.1 0.8 0.1 1" />
             <plugin instance="compositecable0_" />
            
            <body name="q0_cable_B_8" pos="0.015 0 0">
             <joint name="q0_cable_J_8" pos="0 0 0" type="ball" group="3"
                 actuatorfrclimited="false" damping="1e-05" />
             <geom name="q0_cable_G8" size="0.0005 0.0075" pos="0.0075 0 0"
                 quat="0.707107 0 -0.707107 0" type="capsule" condim="1"
                 mass="5e-06" rgba="0.1 0.8 0.1 1" />
             <plugin instance="compositecable0_" />
            
            <body name="q0_cable_B_9" pos="0.015 0 0">
             <joint name="q0_cable_J_9" pos="0 0 0" type="ball" group="3"
                 actuatorfrclimited="false" damping="1e-05" />
             <geom name="q0_cable_G9" size="0.0005 0.0075" pos="0.0075 0 0"
                 quat="0.707107 0 -0.707107 0" type="capsule" condim="1"
                 mass="5e-06" rgba="0.1 0.8 0.1 1" />
             <plugin instance="compositecable0_" />
            
            <body name="q0_cable_B_10" pos="0.015 0 0">
             <joint name="q0_cable_J_10" pos="0 0 0" type="ball" group="3"
                 actuatorfrclimited="false" damping="1e-05" />
             <geom name="q0_cable_G10" size="0.0005 0.0075" pos="0.0075 0 0"
                 quat="0.707107 0 -0.707107 0" type="capsule" condim="1"
                 mass="5e-06" rgba="0.1 0.8 0.1 1" />
             <plugin instance="compositecable0_" />
            
            <body name="q0_cable_B_11" pos="0.015 0 0">
             <joint name="q0_cable_J_11" pos="0 0 0" type="ball" group="3"
                 actuatorfrclimited="false" damping="1e-05" />
             <geom name="q0_cable_G11" size="0.0005 0.0075" pos="0.0075 0 0"
                 quat="0.707107 0 -0.707107 0" type="capsule" condim="1"
                 mass="5e-06" rgba="0.1 0.8 0.1 1" />
             <plugin instance="compositecable0_" />
            
            <body name="q0_cable_B_12" pos="0.015 0 0">
             <joint name="q0_cable_J_12" pos="0 0 0" type="ball" group="3"
                 actuatorfrclimited="false" damping="1e-05" />
             <geom name="q0_cable_G12" size="0.0005 0.0075" pos="0.0075 0 0"
                 quat="0.707107 0 -0.707107 0" type="capsule" condim="1"
                 mass="5e-06" rgba="0.1 0.8 0.1 1" />
             <plugin instance="compositecable0_" />
            
            <body name="q0_cable_B_13" pos="0.015 0 0">
             <joint name="q0_cable_J_13" pos="0 0 0" type="ball" group="3"
                 actuatorfrclimited="false" damping="1e-05" />
             <geom name="q0_cable_G13" size="0.0005 0.0075" pos="0.0075 0 0"
                 quat="0.707107 0 -0.707107 0" type="capsule" condim="1"
                 mass="5e-06" rgba="0.1 0.8 0.1 1" />
             <plugin instance="compositecable0_" />
            
            <body name="q0_cable_B_14" pos="0.015 0 0">
             <joint name="q0_cable_J_14" pos="0 0 0" type="ball" group="3"
                 actuatorfrclimited="false" damping="1e-05" />
             <geom name="q0_cable_G14" size="0.0005 0.0075" pos="0.0075 0 0"
                 quat="0.707107 0 -0.707107 0" type="capsule" condim="1"
                 mass="5e-06" rgba="0.1 0.8 0.1 1" />
             <plugin instance="compositecable0_" />
            
            <body name="q0_cable_B_15" pos="0.015 0 0">
             <joint name="q0_cable_J_15" pos="0 0 0" type="ball" group="3"
                 actuatorfrclimited="false" damping="1e-05" />
             <geom name="q0_cable_G15" size="0.0005 0.0075" pos="0.0075 0 0"
                 quat="0.707107 0 -0.707107 0" type="capsule" condim="1"
                 mass="5e-06" rgba="0.1 0.8 0.1 1" />
             <plugin instance="compositecable0_" />
            
            <body name="q0_cable_B_16" pos="0.015 0 0">
             <joint name="q0_cable_J_16" pos="0 0 0" type="ball" group="3"
                 actuatorfrclimited="false" damping="1e-05" />
             <geom name="q0_cable_G16" size="0.0005 0.0075" pos="0.0075 0 0"
                 quat="0.707107 0 -0.707107 0" type="capsule" condim="1"
                 mass="5e-06" rgba="0.1 0.8 0.1 1" />
             <plugin instance="compositecable0_" />
            
            <body name="q0_cable_B_17" pos="0.015 0 0">
             <joint name="q0_cable_J_17" pos="0 0 0" type="ball" group="3"
                 actuatorfrclimited="false" damping="1e-05" />
             <geom name="q0_cable_G17" size="0.0005 0.0075" pos="0.0075 0 0"
                 quat="0.707107 0 -0.707107 0" type="capsule" condim="1"
                 mass="5e-06" rgba="0.1 0.8 0.1 1" />
             <plugin instance="compositecable0_" />
            
            <body name="q0_cable_B_18" pos="0.015 0 0">
             <joint name="q0_cable_J_18" pos="0 0 0" type="ball" group="3"
                 actuatorfrclimited="false" damping="1e-05" />
             <geom name="q0_cable_G18" size="0.0005 0.0075" pos="0.0075 0 0"
                 quat="0.707107 0 -0.707107 0" type="capsule" condim="1"
                 mass="5e-06" rgba="0.1 0.8 0.1 1" />
             <plugin instance="compositecable0_" />
            
            <body name="q0_cable_B_last" pos="0.015 0 0">
             <joint name="q0_cable_J_last" pos="0 0 0" type="ball" group="3"
                 actuatorfrclimited="false" damping="1e-05" />
             <geom name="q0_cable_G_last" size="0.0005 0.0075" pos="0.0075 0 0"
                 quat="0.707107 0 -0.707107 0" type="capsule" condim="1"
                 mass="5e-06" rgba="0.1 0.8 0.1 1" />
             <site name="q0_cable_S_last" pos="0.015 0 0" group="3" />
             <plugin instance="compositecable0_" />
        
        <body
            name="q0_container"
            pos="0.0157895 0 0"
            >        
            
             <joint
                    type="ball"
                    pos="0 0 0"
                    limited="false"
                    damping="0.00001" />
            
            <site name="q0_attachment" pos="0 0 0" group="5"/>
            <body
                name="q0_cf2"
                childclass="cf2"
                pos="0 0 -0.0015"
                >
                <inertial
                    pos="0 0 0"
                    mass="0.034"
                    diaginertia="1.65717e-05 1.66556e-05 2.92617e-05" />
                
                <geom
                    class="visual"
                    material="propeller_plastic"
                    mesh="cf2_0" />
                <geom
                    class="visual"
                    material="medium_gloss_plastic"
                    mesh="cf2_1" />
                <geom
                    class="visual"
                    material="polished_gold"
                    mesh="cf2_2" />
                <geom
                    class="visual"
                    material="polished_plastic"
                    mesh="cf2_3" />
                <geom
                    class="visual"
                    material="burnished_chrome"
                    mesh="cf2_4" />
                <geom
                    class="visual"
                    material="body_frame_plastic"
                    mesh="cf2_5" />
                <geom
                    class="visual"
                    material="white"
                    mesh="cf2_6" />
                <geom
                    class="collision"
                    mesh="cf2_collision_0" />
                <geom
                    class="collision"
                    mesh="cf2_collision_1" />
                <geom
                    class="collision"
                    mesh="cf2_collision_2" />
                <geom
                    class="collision"
                    mesh="cf2_collision_3" />
                <geom
                    class="collision"
                    mesh="cf2_collision_4" />
                <geom
                    class="collision"
                    mesh="cf2_collision_5" />
                <geom
                    class="collision"
                    mesh="cf2_collision_6" />
                <geom
                    class="collision"
                    mesh="cf2_collision_7" />
                <geom
                    class="collision"
                    mesh="cf2_collision_8" />
                <geom
                    class="collision"
                    mesh="cf2_collision_9" />
                <geom
                    class="collision"
                    mesh="cf2_collision_10" />
                <geom
                    class="collision"
                    mesh="cf2_collision_11" />
                <geom
                    class="collision"
                    mesh="cf2_collision_12" />
                <geom
                    class="collision"
                    mesh="cf2_collision_13" />
                <geom
                    class="collision"
                    mesh="cf2_collision_14" />
                <geom
                    class="collision"
                    mesh="cf2_collision_15" />
                <geom
                    class="collision"
                    mesh="cf2_collision_16" />
                <geom
                    class="collision"
                    mesh="cf2_collision_17" />
                <geom
                    class="collision"
                    mesh="cf2_collision_18" />
                <geom
                    class="collision"
                    mesh="cf2_collision_19" />
                <geom
                    class="collision"
                    mesh="cf2_collision_20" />
                <geom
                    class="collision"
                    mesh="cf2_collision_21" />
                <geom
                    class="collision"
                    mesh="cf2_collision_22" />
                <geom
                    class="collision"
                    mesh="cf2_collision_23" />
                <geom
                    class="collision"
                    mesh="cf2_collision_24" />
                <geom
                    class="collision"
                    mesh="cf2_collision_25" />
                <geom
                    class="collision"
                    mesh="cf2_collision_26" />
                <geom
                    class="collision"
                    mesh="cf2_collision_27" />
                <geom
                    class="collision"
                    mesh="cf2_collision_28" />
                <geom
                    class="collision"
                    mesh="cf2_collision_29" />
                <geom
                    class="collision"
                    mesh="cf2_collision_30" />
                <geom
                    class="collision"
                    mesh="cf2_collision_31" />
                <site
                    name="q0_imu"
                    pos="0 0 0" />
                <site
                    name="q0_thrust1"
                    pos="0.032527 -0.032527 0" />
                <site
                    name="q0_thrust2"
                    pos="-0.032527 -0.032527 0" />
                <site
                    name="q0_thrust3"
                    pos="-0.032527 0.032527 0" />
                <site
                    name="q0_thrust4"
                    pos="0.032527 0.032527 0" />
                
            </body>    
        </body>      
                                                                                       
</body>
</body>
</body>
</body>
</body>
</body>
</body>
</body>
</body>
</body>
</body>
</body>
</body>
</body>
</body>
</body>
</body>
</body>
</body>
</body>
</body>
            <!-- Quad 1 -->
            <body name="q1_cable_chain" pos="0 0 0.01" euler="0 0 1.5707963267948966">
            
        <body name="q1_cable_B_first">
            <joint name="q1_cable_J_first" pos="0 0 0" type="ball" group="3"
                actuatorfrclimited="false" damping="1e-05" />
            <geom name="q1_cable_G0" size="0.0005 0.0075" pos="0.0075 0 0"
            quat="0.707107 0 -0.707107 0" type="capsule" condim="1"
            mass="5e-06" rgba="0.8 0.1 0.1 1" />
            <site name="q1_cable_S_first" pos="0 0 0" group="3" />
            <plugin instance="compositecable1_" />
        
            <body name="q1_cable_B_1" pos="0.015 0 0">
             <joint name="q1_cable_J_1" pos="0 0 0" type="ball" group="3"
                 actuatorfrclimited="false" damping="1e-05" />
             <geom name="q1_cable_G1" size="0.0005 0.0075" pos="0.0075 0 0"
                 quat="0.707107 0 -0.707107 0" type="capsule" condim="1"
                 mass="5e-06" rgba="0.8 0.1 0.1 1" />
             <plugin instance="compositecable1_" />
            
            <body name="q1_cable_B_2" pos="0.015 0 0">
             <joint name="q1_cable_J_2" pos="0 0 0" type="ball" group="3"
                 actuatorfrclimited="false" damping="1e-05" />
             <geom name="q1_cable_G2" size="0.0005 0.0075" pos="0.0075 0 0"
                 quat="0.707107 0 -0.707107 0" type="capsule" condim="1"
                 mass="5e-06" rgba="0.8 0.1 0.1 1" />
             <plugin instance="compositecable1_" />
            
            <body name="q1_cable_B_3" pos="0.015 0 0">
             <joint name="q1_cable_J_3" pos="0 0 0" type="ball" group="3"
                 actuatorfrclimited="false" damping="1e-05" />
             <geom name="q1_cable_G3" size="0.0005 0.0075" pos="0.0075 0 0"
                 quat="0.707107 0 -0.707107 0" type="capsule" condim="1"
                 mass="5e-06" rgba="0.8 0.1 0.1 1" />
             <plugin instance="compositecable1_" />
            
            <body name="q1_cable_B_4" pos="0.015 0 0">
             <joint name="q1_cable_J_4" pos="0 0 0" type="ball" group="3"
                 actuatorfrclimited="false" damping="1e-05" />
             <geom name="q1_cable_G4" size="0.0005 0.0075" pos="0.0075 0 0"
                 quat="0.707107 0 -0.707107 0" type="capsule" condim="1"
                 mass="5e-06" rgba="0.8 0.1 0.1 1" />
             <plugin instance="compositecable1_" />
            
            <body name="q1_cable_B_5" pos="0.015 0 0">
             <joint name="q1_cable_J_5" pos="0 0 0" type="ball" group="3"
                 actuatorfrclimited="false" damping="1e-05" />
             <geom name="q1_cable_G5" size="0.0005 0.0075" pos="0.0075 0 0"
                 quat="0.707107 0 -0.707107 0" type="capsule" condim="1"
                 mass="5e-06" rgba="0.8 0.1 0.1 1" />
             <plugin instance="compositecable1_" />
            
            <body name="q1_cable_B_6" pos="0.015 0 0">
             <joint name="q1_cable_J_6" pos="0 0 0" type="ball" group="3"
                 actuatorfrclimited="false" damping="1e-05" />
             <geom name="q1_cable_G6" size="0.0005 0.0075" pos="0.0075 0 0"
                 quat="0.707107 0 -0.707107 0" type="capsule" condim="1"
                 mass="5e-06" rgba="0.8 0.1 0.1 1" />
             <plugin instance="compositecable1_" />
            
            <body name="q1_cable_B_7" pos="0.015 0 0">
             <joint name="q1_cable_J_7" pos="0 0 0" type="ball" group="3"
                 actuatorfrclimited="false" damping="1e-05" />
             <geom name="q1_cable_G7" size="0.0005 0.0075" pos="0.0075 0 0"
                 quat="0.707107 0 -0.707107 0" type="capsule" condim="1"
                 mass="5e-06" rgba="0.8 0.1 0.1 1" />
             <plugin instance="compositecable1_" />
            
            <body name="q1_cable_B_8" pos="0.015 0 0">
             <joint name="q1_cable_J_8" pos="0 0 0" type="ball" group="3"
                 actuatorfrclimited="false" damping="1e-05" />
             <geom name="q1_cable_G8" size="0.0005 0.0075" pos="0.0075 0 0"
                 quat="0.707107 0 -0.707107 0" type="capsule" condim="1"
                 mass="5e-06" rgba="0.8 0.1 0.1 1" />
             <plugin instance="compositecable1_" />
            
            <body name="q1_cable_B_9" pos="0.015 0 0">
             <joint name="q1_cable_J_9" pos="0 0 0" type="ball" group="3"
                 actuatorfrclimited="false" damping="1e-05" />
             <geom name="q1_cable_G9" size="0.0005 0.0075" pos="0.0075 0 0"
                 quat="0.707107 0 -0.707107 0" type="capsule" condim="1"
                 mass="5e-06" rgba="0.8 0.1 0.1 1" />
             <plugin instance="compositecable1_" />
            
            <body name="q1_cable_B_10" pos="0.015 0 0">
             <joint name="q1_cable_J_10" pos="0 0 0" type="ball" group="3"
                 actuatorfrclimited="false" damping="1e-05" />
             <geom name="q1_cable_G10" size="0.0005 0.0075" pos="0.0075 0 0"
                 quat="0.707107 0 -0.707107 0" type="capsule" condim="1"
                 mass="5e-06" rgba="0.8 0.1 0.1 1" />
             <plugin instance="compositecable1_" />
            
            <body name="q1_cable_B_11" pos="0.015 0 0">
             <joint name="q1_cable_J_11" pos="0 0 0" type="ball" group="3"
                 actuatorfrclimited="false" damping="1e-05" />
             <geom name="q1_cable_G11" size="0.0005 0.0075" pos="0.0075 0 0"
                 quat="0.707107 0 -0.707107 0" type="capsule" condim="1"
                 mass="5e-06" rgba="0.8 0.1 0.1 1" />
             <plugin instance="compositecable1_" />
            
            <body name="q1_cable_B_12" pos="0.015 0 0">
             <joint name="q1_cable_J_12" pos="0 0 0" type="ball" group="3"
                 actuatorfrclimited="false" damping="1e-05" />
             <geom name="q1_cable_G12" size="0.0005 0.0075" pos="0.0075 0 0"
                 quat="0.707107 0 -0.707107 0" type="capsule" condim="1"
                 mass="5e-06" rgba="0.8 0.1 0.1 1" />
             <plugin instance="compositecable1_" />
            
            <body name="q1_cable_B_13" pos="0.015 0 0">
             <joint name="q1_cable_J_13" pos="0 0 0" type="ball" group="3"
                 actuatorfrclimited="false" damping="1e-05" />
             <geom name="q1_cable_G13" size="0.0005 0.0075" pos="0.0075 0 0"
                 quat="0.707107 0 -0.707107 0" type="capsule" condim="1"
                 mass="5e-06" rgba="0.8 0.1 0.1 1" />
             <plugin instance="compositecable1_" />
            
            <body name="q1_cable_B_14" pos="0.015 0 0">
             <joint name="q1_cable_J_14" pos="0 0 0" type="ball" group="3"
                 actuatorfrclimited="false" damping="1e-05" />
             <geom name="q1_cable_G14" size="0.0005 0.0075" pos="0.0075 0 0"
                 quat="0.707107 0 -0.707107 0" type="capsule" condim="1"
                 mass="5e-06" rgba="0.8 0.1 0.1 1" />
             <plugin instance="compositecable1_" />
            
            <body name="q1_cable_B_15" pos="0.015 0 0">
             <joint name="q1_cable_J_15" pos="0 0 0" type="ball" group="3"
                 actuatorfrclimited="false" damping="1e-05" />
             <geom name="q1_cable_G15" size="0.0005 0.0075" pos="0.0075 0 0"
                 quat="0.707107 0 -0.707107 0" type="capsule" condim="1"
                 mass="5e-06" rgba="0.8 0.1 0.1 1" />
             <plugin instance="compositecable1_" />
            
            <body name="q1_cable_B_16" pos="0.015 0 0">
             <joint name="q1_cable_J_16" pos="0 0 0" type="ball" group="3"
                 actuatorfrclimited="false" damping="1e-05" />
             <geom name="q1_cable_G16" size="0.0005 0.0075" pos="0.0075 0 0"
                 quat="0.707107 0 -0.707107 0" type="capsule" condim="1"
                 mass="5e-06" rgba="0.8 0.1 0.1 1" />
             <plugin instance="compositecable1_" />
            
            <body name="q1_cable_B_17" pos="0.015 0 0">
             <joint name="q1_cable_J_17" pos="0 0 0" type="ball" group="3"
                 actuatorfrclimited="false" damping="1e-05" />
             <geom name="q1_cable_G17" size="0.0005 0.0075" pos="0.0075 0 0"
                 quat="0.707107 0 -0.707107 0" type="capsule" condim="1"
                 mass="5e-06" rgba="0.8 0.1 0.1 1" />
             <plugin instance="compositecable1_" />
            
            <body name="q1_cable_B_18" pos="0.015 0 0">
             <joint name="q1_cable_J_18" pos="0 0 0" type="ball" group="3"
                 actuatorfrclimited="false" damping="1e-05" />
             <geom name="q1_cable_G18" size="0.0005 0.0075" pos="0.0075 0 0"
                 quat="0.707107 0 -0.707107 0" type="capsule" condim="1"
                 mass="5e-06" rgba="0.8 0.1 0.1 1" />
             <plugin instance="compositecable1_" />
            
            <body name="q1_cable_B_last" pos="0.015 0 0">
             <joint name="q1_cable_J_last" pos="0 0 0" type="ball" group="3"
                 actuatorfrclimited="false" damping="1e-05" />
             <geom name="q1_cable_G_last" size="0.0005 0.0075" pos="0.0075 0 0"
                 quat="0.707107 0 -0.707107 0" type="capsule" condim="1"
                 mass="5e-06" rgba="0.8 0.1 0.1 1" />
             <site name="q1_cable_S_last" pos="0.015 0 0" group="3" />
             <plugin instance="compositecable1_" />
        
        <body
            name="q1_container"
            pos="0.0157895 0 0"
            >        
            
             <joint
                    type="ball"
                    pos="0 0 0"
                    limited="false"
                    damping="0.00001" />
            
            <site name="q1_attachment" pos="0 0 0" group="5"/>
            <body
                name="q1_cf2"
                childclass="cf2"
                pos="0 0 -0.0015"
                >
                <inertial
                    pos="0 0 0"
                    mass="0.034"
                    diaginertia="1.65717e-05 1.66556e-05 2.92617e-05" />
                
                <geom
                    class="visual"
                    material="propeller_plastic"
                    mesh="cf2_0" />
                <geom
                    class="visual"
                    material="medium_gloss_plastic"
                    mesh="cf2_1" />
                <geom
                    class="visual"
                    material="polished_gold"
                    mesh="cf2_2" />
                <geom
                    class="visual"
                    material="polished_plastic"
                    mesh="cf2_3" />
                <geom
                    class="visual"
                    material="burnished_chrome"
                    mesh="cf2_4" />
                <geom
                    class="visual"
                    material="body_frame_plastic"
                    mesh="cf2_5" />
                <geom
                    class="visual"
                    material="white"
                    mesh="cf2_6" />
                <geom
                    class="collision"
                    mesh="cf2_collision_0" />
                <geom
                    class="collision"
                    mesh="cf2_collision_1" />
                <geom
                    class="collision"
                    mesh="cf2_collision_2" />
                <geom
                    class="collision"
                    mesh="cf2_collision_3" />
                <geom
                    class="collision"
                    mesh="cf2_collision_4" />
                <geom
                    class="collision"
                    mesh="cf2_collision_5" />
                <geom
                    class="collision"
                    mesh="cf2_collision_6" />
                <geom
                    class="collision"
                    mesh="cf2_collision_7" />
                <geom
                    class="collision"
                    mesh="cf2_collision_8" />
                <geom
                    class="collision"
                    mesh="cf2_collision_9" />
                <geom
                    class="collision"
                    mesh="cf2_collision_10" />
                <geom
                    class="collision"
                    mesh="cf2_collision_11" />
                <geom
                    class="collision"
                    mesh="cf2_collision_12" />
                <geom
                    class="collision"
                    mesh="cf2_collision_13" />
                <geom
                    class="collision"
                    mesh="cf2_collision_14" />
                <geom
                    class="collision"
                    mesh="cf2_collision_15" />
                <geom
                    class="collision"
                    mesh="cf2_collision_16" />
                <geom
                    class="collision"
                    mesh="cf2_collision_17" />
                <geom
                    class="collision"
                    mesh="cf2_collision_18" />
                <geom
                    class="collision"
                    mesh="cf2_collision_19" />
                <geom
                    class="collision"
                    mesh="cf2_collision_20" />
                <geom
                    class="collision"
                    mesh="cf2_collision_21" />
                <geom
                    class="collision"
                    mesh="cf2_collision_22" />
                <geom
                    class="collision"
                    mesh="cf2_collision_23" />
                <geom
                    class="collision"
                    mesh="cf2_collision_24" />
                <geom
                    class="collision"
                    mesh="cf2_collision_25" />
                <geom
                    class="collision"
                    mesh="cf2_collision_26" />
                <geom
                    class="collision"
                    mesh="cf2_collision_27" />
                <geom
                    class="collision"
                    mesh="cf2_collision_28" />
                <geom
                    class="collision"
                    mesh="cf2_collision_29" />
                <geom
                    class="collision"
                    mesh="cf2_collision_30" />
                <geom
                    class="collision"
                    mesh="cf2_collision_31" />
                <site
                    name="q1_imu"
                    pos="0 0 0" />
                <site
                    name="q1_thrust1"
                    pos="0.032527 -0.032527 0" />
                <site
                    name="q1_thrust2"
                    pos="-0.032527 -0.032527 0" />
                <site
                    name="q1_thrust3"
                    pos="-0.032527 0.032527 0" />
                <site
                    name="q1_thrust4"
                    pos="0.032527 0.032527 0" />
                
            </body>    
        </body>      
                                                                                       
</body>
</body>
</body>
</body>
</body>
</body>
</body>
</body>
</body>
</body>
</body>
</body>
</body>
</body>
</body>
</body>
</body>
</body>
</body>
</body>
</body>
        </body>
    </worldbody>

    <contact>
        <exclude body1="q0_cable_B_first" body2="q0_cable_B_1" />
<exclude body1="q0_cable_B_1" body2="q0_cable_B_2" />
<exclude body1="q0_cable_B_2" body2="q0_cable_B_3" />
<exclude body1="q0_cable_B_3" body2="q0_cable_B_4" />
<exclude body1="q0_cable_B_4" body2="q0_cable_B_5" />
<exclude body1="q0_cable_B_5" body2="q0_cable_B_6" />
<exclude body1="q0_cable_B_6" body2="q0_cable_B_7" />
<exclude body1="q0_cable_B_7" body2="q0_cable_B_8" />
<exclude body1="q0_cable_B_8" body2="q0_cable_B_9" />
<exclude body1="q0_cable_B_9" body2="q0_cable_B_10" />
<exclude body1="q0_cable_B_10" body2="q0_cable_B_11" />
<exclude body1="q0_cable_B_11" body2="q0_cable_B_12" />
<exclude body1="q0_cable_B_12" body2="q0_cable_B_13" />
<exclude body1="q0_cable_B_13" body2="q0_cable_B_14" />
<exclude body1="q0_cable_B_14" body2="q0_cable_B_15" />
<exclude body1="q0_cable_B_15" body2="q0_cable_B_16" />
<exclude body1="q0_cable_B_16" body2="q0_cable_B_17" />
<exclude body1="q0_cable_B_17" body2="q0_cable_B_18" />
<exclude body1="q0_cable_B_18" body2="q0_cable_B_last" />
<exclude body1="q0_cable_B_first" body2="payload" />
<exclude body1="q1_cable_B_first" body2="q1_cable_B_1" />
<exclude body1="q1_cable_B_1" body2="q1_cable_B_2" />
<exclude body1="q1_cable_B_2" body2="q1_cable_B_3" />
<exclude body1="q1_cable_B_3" body2="q1_cable_B_4" />
<exclude body1="q1_cable_B_4" body2="q1_cable_B_5" />
<exclude body1="q1_cable_B_5" body2="q1_cable_B_6" />
<exclude body1="q1_cable_B_6" body2="q1_cable_B_7" />
<exclude body1="q1_cable_B_7" body2="q1_cable_B_8" />
<exclude body1="q1_cable_B_8" body2="q1_cable_B_9" />
<exclude body1="q1_cable_B_9" body2="q1_cable_B_10" />
<exclude body1="q1_cable_B_10" body2="q1_cable_B_11" />
<exclude body1="q1_cable_B_11" body2="q1_cable_B_12" />
<exclude body1="q1_cable_B_12" body2="q1_cable_B_13" />
<exclude body1="q1_cable_B_13" body2="q1_cable_B_14" />
<exclude body1="q1_cable_B_14" body2="q1_cable_B_15" />
<exclude body1="q1_cable_B_15" body2="q1_cable_B_16" />
<exclude body1="q1_cable_B_16" body2="q1_cable_B_17" />
<exclude body1="q1_cable_B_17" body2="q1_cable_B_18" />
<exclude body1="q1_cable_B_18" body2="q1_cable_B_last" />
<exclude body1="q1_cable_B_first" body2="payload" />

    </contact>

    <tendon>
        
    </tendon>

    <equality>
        <weld site1="q0_start" site2="q0_imu" solref="0.01 4" />
<weld site1="q1_start" site2="q1_imu" solref="0.01 4" />
       
    </equality>

    <actuator>
        <general name="q0_thrust1" class="cf2" site="q0_thrust1" ctrlrange="0 0.14" gear="0 0 1 0 0 6e-06" />
<general name="q0_thrust2" class="cf2" site="q0_thrust2" ctrlrange="0 0.14" gear="0 0 1 0 0 -6e-06" />
<general name="q0_thrust3" class="cf2" site="q0_thrust3" ctrlrange="0 0.14" gear="0 0 1 0 0 6e-06" />
<general name="q0_thrust4" class="cf2" site="q0_thrust4" ctrlrange="0 0.14" gear="0 0 1 0 0 -6e-06" />
<general name="q1_thrust1" class="cf2" site="q1_thrust1" ctrlrange="0 0.14" gear="0 0 1 0 0 6e-06" />
<general name="q1_thrust2" class="cf2" site="q1_thrust2" ctrlrange="0 0.14" gear="0 0 1 0 0 -6e-06" />
<general name="q1_thrust3" class="cf2" site="q1_thrust3" ctrlrange="0 0.14" gear="0 0 1 0 0 6e-06" />
<general name="q1_thrust4" class="cf2" site="q1_thrust4" ctrlrange="0 0.14" gear="0 0 1 0 0 -6e-06" />

    </actuator>

    <sensor>
        <gyro site="q0_imu" name="q0_gyro" />
<accelerometer site="q0_imu" name="q0_linacc" />
<framequat objtype="site" objname="q0_imu" name="q0_framequat" />
<force name="q0_cable_force" site="q0_attachment" />
<gyro site="q1_imu" name="q1_gyro" />
<accelerometer site="q1_imu" name="q1_linacc" />
<framequat objtype="site" objname="q1_imu" name="q1_framequat" />
<force name="q1_cable_force" site="q1_attachment" />

    </sensor>
</mujoco>